
<mujoco model="h1">
    <option gravity="0 0 0" timestep="0.001" />
	<include file="scene.xml"/>
    <compiler angle="radian" meshdir="./meshes/" />
    <size njmax="500" nconmax="100" />
    <option cone="elliptic" impratio="10"/>
    
    
    <asset>
        <mesh name="L_hand_base_link" file="L_hand_base_link.STL" />
        <mesh name="Link11_L" file="Link11_L.STL" />
        <mesh name="Link12_L" file="Link12_L.STL" />
        <mesh name="Link13_L" file="Link13_L.STL" />
        <mesh name="Link14_L" file="Link14_L.STL" />
        <mesh name="Link15_L" file="Link15_L.STL" />
        <mesh name="Link16_L" file="Link16_L.STL" />
        <mesh name="Link17_L" file="Link17_L.STL" />
        <mesh name="Link18_L" file="Link18_L.STL" />
        <mesh name="Link19_L" file="Link19_L.STL" />
        <mesh name="Link20_L" file="Link20_L.STL" />
        <mesh name="Link21_L" file="Link21_L.STL" />
        <mesh name="Link22_L" file="Link22_L.STL" />
    </asset>
    <worldbody>
        <geom type="mesh" contype="0" conaffinity="0" group="1" rgba="0.1 0.1 0.1 1" mesh="L_hand_base_link"  />
        <geom type="mesh" rgba="0.1 0.1 0.1 1" mesh="L_hand_base_link" />
        <body name="L_thumb_proximal_base" pos="-0.01696 -0.0691 0.02045" quat="0.499998 0.5 -0.5 0.500002">
            <inertial pos="0.0048817 0.00038782 -0.00722" quat="0.445981 0.352284 0.495833 0.656617" mass="0.018869" diaginertia="0.001 0.001 0.001" />
            <joint name="L_thumb_proximal_yaw_joint" pos="0 0 0" axis="0 0 1" limited="true" range="-0.1 1.3" damping="0.01"/>
            <geom type="mesh" contype="0" conaffinity="0" group="1" rgba="0.1 0.1 0.1 1" mesh="Link11_L" />
            <!-- <geom type="mesh" rgba="0.1 0.1 0.1 1" mesh="Link11_L" /> -->
            <body name="L_thumb_proximal" pos="0.0099867 0.0098242 -0.0089" quat="0.704571 -0.704573 -0.0598169 0.0598167">
                <inertial pos="0.021936 -0.01279 -0.0080386" quat="0.25452 0.660687 -0.251949 0.659723" mass="0.0066101" diaginertia="0.001 0.001 0.001" />
                <joint name="L_thumb_proximal_pitch_joint" pos="0 0 0" axis="0 0 -1" limited="true" range="0 0.5" />
                <geom type="mesh" contype="0" conaffinity="0" group="1" rgba="0.1 0.1 0.1 1" mesh="Link12_L" />
                <!-- <geom type="mesh" rgba="0.1 0.1 0.1 1" mesh="Link12_L" /> -->
                <body name="L_thumb_intermediate" pos="0.04407 -0.034553 -0.0008">
                    <inertial pos="0.0095531 0.0016282 -0.0072002" quat="0.30738 0.636732 -0.307526 0.636803" mass="0.0037844" diaginertia="0.001 0.001 0.001" />
                    <joint name="L_thumb_intermediate_joint" pos="0 0 0" axis="0 0 -1" limited="true" range="0 0.8" />
                    <geom type="mesh" contype="0" conaffinity="0" group="1" rgba="0.1 0.1 0.1 1" mesh="Link13_L" />
                    <!-- <geom type="mesh" rgba="0.1 0.1 0.1 1" mesh="Link13_L" /> -->
                    <body name="L_thumb_distal" pos="0.020248 -0.010156 -0.0012">
                        <inertial pos="0.0092888 -0.004953 -0.0060033" quat="0.266264 0.65596 -0.262836 0.655544" mass="0.003344" diaginertia="0.001 0.001 0.001" />
                        <joint name="L_thumb_distal_joint" pos="0 0 0" axis="0 0 -1" limited="true" range="0 1.2" />
                        <geom type="mesh" contype="0" conaffinity="0" group="1" rgba="0.1 0.1 0.1 1" mesh="Link14_L" />
                        <!-- <geom type="mesh" rgba="0.1 0.1 0.1 1" mesh="Link14_L" /> -->
                        <!-- <geom size="0.005" pos="0.015 -0.013 -0.004" contype="0" conaffinity="0" group="1" rgba="0 1 0 1" /> -->
                    </body>
                </body>
            </body>
        </body>
        <body name="L_index_proximal" pos="0.00028533 -0.13653 0.032268" quat="0.999848 -0.0174526 0 0">
            <inertial pos="0.0012971 -0.011934 -0.0059998" quat="0.489677 0.510115 -0.489692 0.510099" mass="0.0042405" diaginertia="0.001 0.001 0.001" />
            <joint name="L_index_proximal_joint" pos="0 0 0" axis="0 0 -1" limited="true" range="0 1.7" />
            <geom type="mesh" contype="0" conaffinity="0" group="1" rgba="0.1 0.1 0.1 1" mesh="Link15_L" />
            <!-- <geom type="mesh" rgba="0.1 0.1 0.1 1" mesh="Link15_L" /> -->
            <body name="L_index_intermediate" pos="-0.0024229 -0.032041 -0.001">
                <inertial pos="0.0021753 -0.019567 -0.005" quat="0.528694 0.469555 -0.528694 0.469555" mass="0.0045682" diaginertia="0.001 0.001 0.001" />
                <joint name="L_index_intermediate_joint" pos="0 0 0" axis="0 0 -1" limited="true" range="0 1.7" />
                <geom type="mesh" contype="0" conaffinity="0" group="1" rgba="0.1 0.1 0.1 1" mesh="Link16_L" />
                <!-- <geom type="mesh" rgba="0.1 0.1 0.1 1" mesh="Link16_L" /> -->
                <!-- <geom size="0.005" pos="-0.005 -0.04 -0.004" contype="0" conaffinity="0" group="1" rgba="0 1 0 1" /> -->
            </body>
        </body>
        <body name="L_middle_proximal" pos="0.00028533 -0.1371 0.01295">
            <inertial pos="0.0012971 -0.011934 -0.0059999" quat="0.489677 0.510115 -0.489692 0.510099" mass="0.0042405" diaginertia="0.001 0.001 0.001" />
            <joint name="L_middle_proximal_joint" pos="0 0 0" axis="0 0 -1" limited="true" range="0 1.7" />
            <geom type="mesh" contype="0" conaffinity="0" group="1" rgba="0.1 0.1 0.1 1" mesh="Link17_L" />
            <!-- <geom type="mesh" rgba="0.1 0.1 0.1 1" mesh="Link17_L" /> -->
            <body name="L_middle_intermediate" pos="-0.0024229 -0.032041 -0.001">
                <inertial pos="0.001921 -0.020796 -0.0049999" quat="0.531603 0.466115 -0.531728 0.466262" mass="0.0050397" diaginertia="0.001 0.001 0.001" />
                <joint name="L_middle_intermediate_joint" pos="0 0 0" axis="0 0 -1" limited="true" range="0 1.7" />
                <geom type="mesh" contype="0" conaffinity="0" group="1" rgba="0.1 0.1 0.1 1" mesh="Link18_L" />
                <!-- <geom type="mesh" rgba="0.1 0.1 0.1 1" mesh="Link18_L" /> -->
                <!-- <geom size="0.005" pos="-0.005 -0.045 -0.004" contype="0" conaffinity="0" group="1" rgba="0 1 0 1" /> -->
            </body>
        </body>
        <body name="L_ring_proximal" pos="0.00028533 -0.13691 -0.0062872" quat="0.999657 0.026177 0 0">
            <inertial pos="0.0012971 -0.011934 -0.0059999" quat="0.489677 0.510114 -0.489692 0.510099" mass="0.0042405" diaginertia="0.001 0.001 0.001" />
            <joint name="L_ring_proximal_joint" pos="0 0 0" axis="0 0 -1" limited="true" range="0 1.7" />
            <geom type="mesh" contype="0" conaffinity="0" group="1" rgba="0.1 0.1 0.1 1" mesh="Link19_L" />
            <!-- <geom type="mesh" rgba="0.1 0.1 0.1 1" mesh="Link19_L" /> -->
            <body name="L_ring_intermediate" pos="-0.0024229 -0.032041 -0.001">
                <inertial pos="0.0021753 -0.019567 -0.005" quat="0.528694 0.469556 -0.528694 0.469556" mass="0.0045682" diaginertia="0.001 0.001 0.001" />
                <joint name="L_ring_intermediate_joint" pos="0 0 0" axis="0 0 -1" limited="true" range="0 1.7" />
                <geom type="mesh" contype="0" conaffinity="0" group="1" rgba="0.1 0.1 0.1 1" mesh="Link20_L" />
                <!-- <geom type="mesh" rgba="0.1 0.1 0.1 1" mesh="Link20_L" /> -->
                <!-- <geom size="0.005" pos="-0.002 -0.04 -0.004" contype="0" conaffinity="0" group="1" rgba="0 1 0 1" /> -->
            </body>
        </body>
        <body name="L_pinky_proximal" pos="0.00028533 -0.13571 -0.025488" quat="0.99863 0.0523361 0 0">
            <inertial pos="0.0012971 -0.011934 -0.0059999" quat="0.489677 0.510114 -0.489692 0.510099" mass="0.0042405" diaginertia="0.001 0.001 0.001" />
            <joint name="L_pinky_proximal_joint" pos="0 0 0" axis="0 0 -1" limited="true" range="0 1.7" />
            <geom type="mesh" contype="0" conaffinity="0" group="1" rgba="0.1 0.1 0.1 1" mesh="Link21_L" />
            <!-- <geom type="mesh" rgba="0.1 0.1 0.1 1" mesh="Link21_L" /> -->
            <body name="L_pinky_intermediate" pos="-0.0024229 -0.032041 -0.001">
                <inertial pos="0.0024788 -0.016208 -0.0050001" quat="0.526797 0.471683 -0.526793 0.471687" mass="0.0036036" diaginertia="0.001 0.001 0.001" />
                <joint name="L_pinky_intermediate_joint" pos="0 0 0" axis="0 0 -1" limited="true" range="0 1.7" />
                <geom type="mesh" contype="0" conaffinity="0" group="1" rgba="0.1 0.1 0.1 1" mesh="Link22_L" />
                <!-- <geom type="mesh" rgba="0.1 0.1 0.1 1" mesh="Link22_L" /> -->
                <!-- <geom size="0.005" pos="-0.002 -0.032 -0.004" contype="0" conaffinity="0" group="1" rgba="0 1 0 1" /> -->
            </body>
        </body>
    </worldbody>
    
    
    <actuator>
        <position joint="L_thumb_proximal_yaw_joint"   ctrlrange="-0.1 1.3" kp="100"  user="1"/>
        <position joint="L_thumb_proximal_pitch_joint"   ctrlrange="-3.14 3.14" kp="100"  user="1"/>
        <position joint="L_thumb_intermediate_joint"  ctrlrange="-3.14 3.14" kp="100"  user="1"/>
        <position joint="L_thumb_distal_joint"  ctrlrange="-0 3.14" kp="100"  user="1"/>
        <position joint="L_index_proximal_joint"  ctrlrange="-1.57 .57" kp="100"  user="1"/>
        <position joint="L_index_intermediate_joint"  ctrlrange="-1.57 1.57" kp="100"  user="1"/>
	 </actuator>
	
</mujoco>
