<mujoco model="h1">
    <compiler angle="radian" meshdir="./meshes/" />
    <size njmax="500" nconmax="100" />
    <asset>
        <mesh name="R_hand_base_link" file="R_hand_base_link.STL" />
        <mesh name="Link11_R" file="Link11_R.STL" />
        <mesh name="Link12_R" file="Link12_R.STL" />
        <mesh name="Link13_R" file="Link13_R.STL" />
        <mesh name="Link14_R" file="Link14_R.STL" />
        <mesh name="Link15_R" file="Link15_R.STL" />
        <mesh name="Link16_R" file="Link16_R.STL" />
        <mesh name="Link17_R" file="Link17_R.STL" />
        <mesh name="Link18_R" file="Link18_R.STL" />
        <mesh name="Link19_R" file="Link19_R.STL" />
        <mesh name="Link20_R" file="Link20_R.STL" />
        <mesh name="Link21_R" file="Link21_R.STL" />
        <mesh name="Link22_R" file="Link22_R.STL" />
    </asset>
    <worldbody>
        <geom type="mesh" contype="0" conaffinity="0" group="1" rgba="0.1 0.1 0.1 1" mesh="R_hand_base_link" />
        <!-- <geom type="mesh" rgba="0.1 0.1 0.1 1" mesh="R_hand_base_link" /> -->
        <body name="R_thumb_proximal_base" pos="-0.01696 -0.0691 -0.02045" quat="0.499998 0.5 -0.5 0.500002">
            <inertial pos="-0.0048064 0.0009382 -0.00757" quat="0.515015 0.680854 0.408023 0.323596" mass="0.0018869" diaginertia="8.66026e-08 6.8732e-08 4.94194e-08" />
            <joint name="R_thumb_proximal_yaw_joint" pos="0 0 0" axis="0 0 -1" limited="true" range="-0.1 1.3" />
            <geom type="mesh" contype="0" conaffinity="0" group="1" rgba="0.1 0.1 0.1 1" mesh="Link11_R" />
            <!-- <geom type="mesh" rgba="0.1 0.1 0.1 1" mesh="Link11_R" /> -->
            <body name="R_thumb_proximal" pos="-0.0088099 0.010892 -0.00925" quat="0.0996843 0.0996847 0.700046 0.700044">
                <inertial pos="0.021932 0.012785 -0.0080386" quat="-0.254474 0.660716 0.251893 0.659733" mass="0.0066075" diaginertia="2.78601e-06 2.43933e-06 8.64566e-07" />
                <joint name="R_thumb_proximal_pitch_joint" pos="0 0 0" axis="0 0 1" limited="true" range="0 0.5" />
                <geom type="mesh" contype="0" conaffinity="0" group="1" rgba="0.1 0.1 0.1 1" mesh="Link12_R" />
                <!-- <geom type="mesh" rgba="0.1 0.1 0.1 1" mesh="Link12_R" /> -->
                <body name="R_thumb_intermediate" pos="0.04407 0.034553 -0.0008">
                    <inertial pos="0.0095544 -0.0016282 -0.0071997" quat="0.636718 0.307389 -0.636802 0.307548" mass="0.0037847" diaginertia="4.6531e-07 4.48089e-07 2.45661e-07" />
                    <joint name="R_thumb_intermediate_joint" pos="0 0 0" axis="0 0 1" limited="true" range="0 0.8" />
                    <geom type="mesh" contype="0" conaffinity="0" group="1" rgba="0.1 0.1 0.1 1" mesh="Link13_R" />
                    <!-- <geom type="mesh" rgba="0.1 0.1 0.1 1" mesh="Link13_R" /> -->
                    <body name="R_thumb_distal" pos="0.020248 0.010156 -0.0012">
                        <inertial pos="0.0092888 0.0049529 -0.0060033" quat="-0.266294 0.655967 0.262806 0.655537" mass="0.0033441" diaginertia="2.0026e-07 1.95247e-07 8.1593e-08" />
                        <joint name="R_thumb_distal_joint" pos="0 0 0" axis="0 0 1" limited="true" range="0 1.2" />
                        <geom type="mesh" contype="0" conaffinity="0" group="1" rgba="0.1 0.1 0.1 1" mesh="Link14_R" />
                        <!-- <geom type="mesh" rgba="0.1 0.1 0.1 1" mesh="Link14_R" /> -->
                        <geom size="0.005" pos="0.015 0.013 -0.004" contype="0" conaffinity="0" group="1" rgba="0 1 0 1" />
                    </body>
                </body>
            </body>
        </body>
        <body name="R_index_proximal" pos="0.00028533 -0.13653 -0.032268" quat="0.0174454 -0.999848 0 0">
            <inertial pos="0.0012259 0.011942 -0.0060001" quat="0.50867 0.49121 -0.508643 0.491172" mass="0.0042403" diaginertia="6.9398e-07 6.62871e-07 2.10909e-07" />
            <joint name="R_index_proximal_joint" pos="0 0 0" axis="0 0 1" limited="true" range="0 1.7" />
            <geom type="mesh" contype="0" conaffinity="0" group="1" rgba="0.1 0.1 0.1 1" mesh="Link15_R" />
            <!-- <geom type="mesh" rgba="0.1 0.1 0.1 1" mesh="Link15_R" /> -->
            <body name="R_index_intermediate" pos="-0.0026138 0.032026 -0.001">
                <inertial pos="0.0019697 0.019589 -0.005" quat="0.466773 0.531152 -0.466773 0.531153" mass="0.0045683" diaginertia="7.8179e-07 7.72465e-07 8.47212e-08" />
                <joint name="R_index_intermediate_joint" pos="0 0 0" axis="0 0 1" limited="true" range="0 1.7" />
                <geom type="mesh" contype="0" conaffinity="0" group="1" rgba="0.1 0.1 0.1 1" mesh="Link16_R" />
                <!-- <geom type="mesh" rgba="0.1 0.1 0.1 1" mesh="Link16_R" /> -->
                <geom size="0.005" pos="-0.005 0.04 -0.004" contype="0" conaffinity="0" group="1" rgba="0 1 0 1" />
            </body>
        </body>
        <body name="R_middle_proximal" pos="0.00028533 -0.1371 -0.01295" quat="-3.67321e-06 -1 0 0">
            <inertial pos="0.001297 0.011934 -0.0060001" quat="0.510131 0.489693 -0.510105 0.489653" mass="0.0042403" diaginertia="6.9397e-07 6.62865e-07 2.10915e-07" />
            <joint name="R_middle_proximal_joint" pos="0 0 0" axis="0 0 1" limited="true" range="0 1.7" />
            <geom type="mesh" contype="0" conaffinity="0" group="1" rgba="0.1 0.1 0.1 1" mesh="Link17_R" />
            <!-- <geom type="mesh" rgba="0.1 0.1 0.1 1" mesh="Link17_R" /> -->
            <body name="R_middle_intermediate" pos="-0.0024229 0.032041 -0.001">
                <inertial pos="0.001921 0.020796 -0.005" quat="0.466148 0.531627 -0.466229 0.531705" mass="0.0050396" diaginertia="9.8384e-07 9.73279e-07 9.14014e-08" />
                <joint name="R_middle_intermediate_joint" pos="0 0 0" axis="0 0 1" limited="true" range="0 1.7" />
                <geom type="mesh" contype="0" conaffinity="0" group="1" rgba="0.1 0.1 0.1 1" mesh="Link18_R" />
                <!-- <geom type="mesh" rgba="0.1 0.1 0.1 1" mesh="Link18_R" /> -->
                <geom size="0.005" pos="-0.005 0.045 -0.004" contype="0" conaffinity="0" group="1" rgba="0 1 0 1" />
            </body>
        </body>
        <body name="R_ring_proximal" pos="0.00028533 -0.13691 0.0062872" quat="0.0261933 0.999657 0 0">
            <inertial pos="0.001297 0.011934 -0.0060002" quat="0.510129 0.489691 -0.510107 0.489654" mass="0.0042403" diaginertia="6.9397e-07 6.62865e-07 2.10915e-07" />
            <joint name="R_ring_proximal_joint" pos="0 0 0" axis="0 0 1" limited="true" range="0 1.7" />
            <geom type="mesh" contype="0" conaffinity="0" group="1" rgba="0.1 0.1 0.1 1" mesh="Link19_R" />
            <!-- <geom type="mesh" rgba="0.1 0.1 0.1 1" mesh="Link19_R" /> -->
            <body name="R_ring_intermediate" pos="-0.0024229 0.032041 -0.001">
                <inertial pos="0.0021753 0.019567 -0.005" quat="0.469554 0.528695 -0.469554 0.528695" mass="0.0045683" diaginertia="7.8177e-07 7.72448e-07 8.4722e-08" />
                <joint name="R_ring_intermediate_joint" pos="0 0 0" axis="0 0 1" limited="true" range="0 1.7" />
                <geom type="mesh" contype="0" conaffinity="0" group="1" rgba="0.1 0.1 0.1 1" mesh="Link20_R" />
                <!-- <geom type="mesh" rgba="0.1 0.1 0.1 1" mesh="Link20_R" /> -->
                <geom size="0.005" pos="-0.002 0.04 -0.004" contype="0" conaffinity="0" group="1" rgba="0 1 0 1" />
            </body>
        </body>
        <body name="R_pinky_proximal" pos="0.00028533 -0.13571 0.025488" quat="0.0523224 0.99863 0 0">
            <inertial pos="0.001297 0.011934 -0.0060001" quat="0.51013 0.489693 -0.510106 0.489653" mass="0.0042403" diaginertia="6.9397e-07 6.62865e-07 2.10915e-07" />
            <joint name="R_pinky_proximal_joint" pos="0 0 0" axis="0 0 1" limited="true" range="0 1.7" />
            <geom type="mesh" contype="0" conaffinity="0" group="1" rgba="0.1 0.1 0.1 1" mesh="Link21_R" />
            <!-- <geom type="mesh" rgba="0.1 0.1 0.1 1" mesh="Link21_R" /> -->
            <body name="R_pinky_intermediate" pos="-0.0024229 0.032041 -0.001">
                <inertial pos="0.0024748 0.016203 -0.0050031" quat="0.47398 0.528862 -0.469291 0.524799" mass="0.0035996" diaginertia="4.4867e-07 4.43723e-07 6.56538e-08" />
                <joint name="R_pinky_intermediate_joint" pos="0 0 0" axis="0 0 1" limited="true" range="0 1.7" />
                <geom type="mesh" contype="0" conaffinity="0" group="1" rgba="0.1 0.1 0.1 1" mesh="Link22_R" />
                <!-- <geom type="mesh" rgba="0.1 0.1 0.1 1" mesh="Link22_R" /> -->
                <geom size="0.005" pos="-0.002 0.032 -0.004" contype="0" conaffinity="0" group="1" rgba="0 1 0 1" />
            </body>
        </body>
    </worldbody>
</mujoco>
